Workbook

Sheet Appendix C1
A1: APPENDIX C-1 : FINANCIAL PROPOSAL SUBMISSION FORM
A2: FROM : (Name of Firm) | G2: To Regional Office, Chandigarh National Highways Authority of India, NHAI Building, Sector - 30B, Chandigarh (UT) - 160030, (Near Sector – 29-30 Traffic Light, Opposite 30 C Market) Tel: 0172 - 2586818 Fax: 0172-2573030. E-mail: tendersrochandigarh@nhai.org
A3: Subject: | B3: Supervision Consultant Services during Operation & Maintenance period for 4/6 of Yamunanagar-Saha-Barwala-Panchkula section of NH-73 (New NH-344 & 07) from km. 71.400 to km. 176.400 in the State of Haryana.
A4: We, the undersigned, offer to provide the consulting services for the above in accordance with your
A5: Request for Proposal dated | D5: [Date], | E5: and our proposal. Our attached financial proposal is for the sum of
A6: [Amount in words and figures] | H6: This amount is exclusive of the local
A7: taxes which we have estimated at | E7: (Amount in Words and Figures).
A8: Our financial proposal shall be binding upon us subject to the modifications resulting from contract negotiations, up
A9: to the expiration of the validity period of the proposal, i.e., | G9: [Date].
A11: We undertake that, in competing for (and, if the award is made to us, in executing) the above contract, we will strictly observe the laws against fraud and corruption in force in India namely “Prevention of Corruption Act 1988”. Commission and gratuities, if any, paid or to be paid by us to agents relating to this proposal and contract execution, if we are awarded the contract, are listed below:
A12: Name and Address of Agents | E12: Amount and Currency | I12: Purpose of Commission or Gratuity
A13: ............................... ............................... | E13: ............................... ............................... | I13: ............................... ...............................
A14: We understand you are not bound to accept any proposal you receive.
A15: We remain, Yours sincerely, Managing Director/Head of the firm/Authorised Representative of the firm* Name of the firm
A17: Address
A19: *Lead Member in case of JV

Sheet Appendix C2
A3: Name of Work` | C3: Supervision Consultant Services during Operation & Maintenance period for 4/6 of Yamunanagar-Saha-Barwala-Panchkula section of NH-73 (New NH-344 & 07) from km. 71.400 to km. 176.400 in the State of Haryana.
A4: APPENDIX C-2 : SUMMARY
A5: NAME OF THE FIRM/COMPANY
C6: Amount
A7: No. | B7: Description | C7: (:LC)*
B9: Local Consultants
A10: I | B10: Remuneration for Local Professional Staff | C10: ='Appendix C3'!G23 -> 0
A11: II | B11: Supporting Staff | C11: ='Appendix C3'!G32 -> 0
A12: III | B12: Transportation | C12: ='Appendix C3'!G40 -> 0
A13: IV | B13: Duty Travel to Site | C13: ='Appendix C3'!G46 -> 0
A14: V | B14: Office Rent | C14: ='Appendix C3'!G52 -> 0
A15: VI | B15: Office Supplies, Utilities and Communication | C15: ='Appendix C3'!G57 -> 0
A16: VII | B16: Office Furniture and Equipment | C16: ='Appendix C3'!G62 -> 0
A17: VIII | B17: Reports and Document Printing | C17: ='Appendix C3'!G69 -> 0
A18: IX | B18: Survey Equipment with Survey Party and Vehicle | C18: ='Appendix C3'!G77 -> 0
B19: Subtotal Local Consultant | C19: =SUM(C10:C18) -> 0
B20: Consultancy Services Tax / GST Payable in India | C20: 0.18
B21: Total Costs (Including GST Tax) | C21: =C19+(C20*C19) -> 0
A23: LC* Local Currency in Rs
A24: Note: Payments will be made as per stipulations of the Conditions of Contract.

Sheet Appendix C3
A1: APPENDIX C-3 : BREAKDOWN OF LOCAL CURRENCY COSTS
A2: Name of Work:- Supervision Consultant Services during Operation & Maintenance period for 4/6 of Yamunanagar-Saha-Barwala-Panchkula section of NH-73 (New NH-344 & 07) from km. 71.400 to km. 176.400 in the State of Haryana.
A3: I. REMUNERATION FOR LOCAL PROFESSIONAL STAFF
A4: No. | B4: Position | D4: Name | E4: Rate | F4: No. of man-months* | G4: Amount
A6: Key Personnel (Professional Staff)
A7: 1 | B7: Team Leader cum Sr. Highway Engineer | D7: TBN | F7: 9 | G7: =F7*E7 -> 0
A8: 2 | B8: Highway Maintenance cum Resident Engineer (2 nos.) | D8: TBN | F8: 72 | G8: =F8*E8 -> 0
A9: 3 | B9: Road Safety Expert | D9: TBN | F9: 9 | G9: =F9*E9 -> 0
A10: 4 | B10: Bridge / Structural Engineer | D10: TBN | F10: 9 | G10: =F10*E10 -> 0
A11: Sub – Total | F11: =F7+F8+F9+F10 -> 99 | G11: =SUM(G7:G10) -> 0
A13: Sub-professional
A14: 1 | B14: Assistant Quality cum Material Expert | D14: TBN | F14: 12 | G14: =F14*E14 -> 0
A15: 2 | B15: Assistant Highway Maintenance Engineer (4 nos.) | D15: TBN | F15: 144 | G15: =F15*E15 -> 0
A16: 3 | B16: Assistant Bridge Engineer (2 nos.) | D16: TBN | F16: 24 | G16: =F16*E16 -> 0
A17: 4 | B17: CAD Expert | D17: TBN | F17: 12 | G17: =F17*E17 -> 0
A18: 5 | B18: Electrical Engineer (2 nos.) | D18: TBN | F18: 24 | G18: =F18*E18 -> 0
A19: 6 | B19: Quantity Surveyor (2 Nos) | D19: TBN | F19: 18 | G19: =F19*E19 -> 0
A20: 7 | B20: Horticulture Expert (2 Nos) | D20: TBN | F20: 18 | G20: =F20*E20 -> 0
A21: 8 | B21: IT expert+ Toll Plaza expert | D21: TBN | F21: 12 | G21: =F21*E21 -> 0
A22: Sub Total | F22: =SUM(F14:F21) -> 264 | G22: =SUM(G14:G21) -> 0
A23: Total | G23: =G22+G11 -> 0
A24: TBN = To Be Named *The man-month against each key personnel/sub – professional shall be same as specified in Enclosure A of TOR.
A26: II. | B26: Support Staff
A27: No. | B27: Position | D27: Name | E27: Staff Months | F27: Billing Rate ( ) | G27: Amount ( )
A28: 1 | B28: Technical Supervisor (2 nos) | D28: TBN | E28: 72 | G28: =+E28*F28 -> 0
A29: 2 | B29: Office Manager | D29: TBN | E29: 36 | G29: =+E29*F29 -> 0
A30: 3 | B30: Steno cum Computer Operator | D30: TBN | E30: 36 | G30: =+E30*F30 -> 0
A31: 4 | B31: Office Boy | D31: TBN | E31: 36 | G31: =+E31*F31 -> 0
F32: Total : | G32: =SUM(G28:G31) -> 0
A33: Note : Billing rates as indicated above shall be increased in accordance of clause 6.2(a) Special Conditions of Contract. However, for evaluation of Bid proposals, the quoted initial rate shall be multiplied by the total time input for each position on this contract, i.e. without considering the increase in the billing rates.
A35: III. | B35: Transportation (Fixed rate on rental basis) The vehicles provided by the Consultants shall include the cost for rental, drivers, operation, maintenance, repairs, insurance, etc. for all complete approx. 4000 km/month run
A36: S.No | B36: Description of Vehicles | C36: Qty. (No. of vehicle-month) | E36: Total | F36: Rate / Vehicle - Month | G36: Amount
C37: No. of months | D37: No. of Vehicles
A38: 1 | B38: Innova Crysta with 2393 cc or Equivalent (for Team Leader/RE) (not more than 3 years old) | C38: 36 | D38: 2 | E38: 72 | G38: =E38*F38 -> 0
A39: 2 | B39: Mahindra Scorpio or equivalent with 2184 cc (for Other Technical Staff) (not more than 3 years old) | C39: 36 | D39: 4 | E39: 144 | G39: =E39*F39 -> 0
A40: Total: | G40: =SUM(G38:G39) -> 0
A42: IV. | B42: Duty Travel to Site (Fixed Costs) : Professional and Sub-Professional Staff
B43: Trips | D43: Number of Trips | F43: Rate* | G43: Amount
B44: To NHAI Regional Office (Round Trip) | D44: 12 | G44: =F44*D44 -> 0
B45: Site to NHAI HQ for Key Professionals (round trips) | D45: 12 | G45: =F45*D45 -> 0
...
